Workbook

Sheet Income Statement
A1: Statement of Profit or Loss and OCI (Rm) | B1: 2018 | C1: 2017 | D1: 2016 | E1: 2015 | F1: 2014 | G1: 2013
A2: Revenue | B2: 200477 | C2: 187095 | D2: 99848 | E2: 43445 | F2: 117364 | G2: 97938
A3: Cost of Sales | B3: -122943 | C3: -114454 | D3: -68873 | E3: -29805 | F3: -75446 | G3: -63542
A4: Gross Profit | B4: 77534 | C4: 72641 | D4: 30975 | E4: 13640 | F4: 41918 | G4: 34396
A5: Other Operating Income | B5: 3054 | C5: 2948 | D5: 4779 | E5: 4587 | F5: 1404 | G5: 1238
A6: Distribution Expenses | B6: -10993 | C6: -8753 | D6: -7060 | E6: -5491 | F6: 0 | G6: 0
A7: Administration Expenses | B7: -64175 | C7: -61138 | D7: -30326 | E7: -15243 | F7: 0 | G7: 0
A8: Other Operating Expenses | B8: -4557 | C8: -8753 | F8: -23640 | G8: -20361
A9: Net Other Income | D9: 3870 | E9: 2397
A10: Operating Profit/(Loss) | B10: 1253 | C10: -2256 | D10: 9298 | E10: 5381 | F10: 14122 | G10: 9459
A11: Finance Costs | B11: -10257 | C11: -6166 | D11: -2536 | E11: -1315 | F11: -3486 | G11: -2624
A12: Income from Investments | B12: 1065 | C12: 572 | D12: 809 | E12: 569 | F12: 1491 | G12: 998
A13: Share of Profit of Equity Accounted Companies | B13: 908 | C13: 1519 | D13: 1291 | E13: 388 | F13: 290 | G13: 240
A14: Impairment of Equity Accounted Companies | B14: -47 | C14: -1895 | E14: -10
A15: Profit/(Loss) Before Taxation | B15: -7078 | C15: -8227 | D15: 8862 | E15: 5013 | F15: 12417 | G15: 8073
A16: Taxation | B16: -3477 | C16: -3008 | D16: -1571 | E16: -228 | F16: -1954 | G16: -983
A17: Profit/(Loss) from Continuing Operations | B17: -10555 | C17: -11235 | D17: 7291 | E17: 4785 | F17: 10463 | G17: 7090
A18: Profit/(Loss) from Discontinued Operations | B18: -8112 | C18: -48829 | D18: 8099 | E18: 6667 | F18: -600 | G18: 859
A19: Profit/(Loss) for the Year | B19: -18667 | C19: -60064 | D19: 15390 | E19: 11452 | F19: 9863 | G19: 7949
A20: Other Comprehensive Income Total | B20: 423 | C20: -2828 | D20: -7889 | E20: -3614 | F20: 5766 | G20: 6312
A21: Total Comprehensive Income | B21: -18244 | C21: -62892 | D21: 7501 | E21: 7838 | F21: 15629 | G21: 14261

Sheet Financial Position
A1: SUMMARISED FINANCIAL STATEMENTS continued
A2: Statement of financial position as at 30 June 2014 | B2: 2018 | C2: 2017 | D2: 2016 | E2: 2015 | F2: 2014 Rm | G2: 2013 Rm | H2: 2012 Rm
A3: ASSETS
A4: Non-current assets
A5: Goodwill | B5: 4485 | C5: 4593 | D5: 47963 | E5: 48548 | F5: 27810 | G5: 18850 | H5: 15572
A6: Intangible assets | B6: 1826 | C6: 2657 | D6: 21369 | E6: 29620 | F6: 38306 | G6: 41585 | H6: 33834
A7: Property, plant and equipment | B7: 2146 | C7: 3302 | D7: 8977 | E7: 43916 | F7: 53995 | G7: 44897 | H7: 34942
A8: Investment property | B8: 134 | C8: 128 | D8: 955 | E8: 1317 | F8: 427 | G8: 480 | H8: 472
A9: Consumable biological assets | E9: 12693 | F9: - | G9: 1761 | H9: 1656
A10: Investments in equity accounted companies | B10: 430 | C10: 2055 | D10: 19269 | E10: 5572 | F10: 4223 | G10: 2634 | H10: 2341
A11: Investments and loans | B11: 311 | C11: 106 | D11: 6437 | E11: 3084 | F11: 10399 | G11: 1124 | H11: 868
A12: Deferred taxation assets | B12: 201 | C12: 221 | D12: 2912 | E12: 150 | F12: 1390 | G12: 730 | H12: 697
A13: Trade and other receivables | B13: 3 | C13: 2 | D13: 81 | F13: 70 | G13: 3174 | H13: 2619
B14: 9536 | C14: 13064 | D14: =SUM(D5:D13) -> 107963 | E14: =SUM(E5:E13) -> 144900 | F14: =SUM(F5:F13) -> 136620 | G14: =SUM(G5:G13) -> 115235 | H14: =SUM(H5:H13) -> 93001
A15: Current assets
A16: Vehicle rental fleet | D16: 0 | E16: 0 | F16: 534 | G16: 455 | H16: 372
A17: Inventories | B17: 2155 | C17: 2556 | D17: 13791 | E17: 27631 | F17: 17921 | G17: 16447 | H17: 14539
A18: Trade and other receivables | B18: 1216 | C18: 1055 | D18: 6039 | E18: 10160 | F18: 18112 | G18: 20039 | H18: 15534
A19: Taxation Received | D19: 263 | E19: 495
A20: Short-term loans receivable | D20: 5938 | E20: 48 | F20: 5928 | G20: 3228 | H20: 1710
A21: Investment & Loans | B21: 261 | C21: 107 | D21: 2942 | E21: 3001
A22: Cash and cash equivalents | B22: 1275 | C22: 723 | D22: 6581 | E22: 7010 | F22: 16341 | G22: 9249 | H22: 8057
B23: 4907 | C23: 4441 | D23: =SUM(D16:D22) -> 35554 | E23: =SUM(E16:E22) -> 48345 | F23: =SUM(F16:F22) -> 58836 | G23: =SUM(G16:G22) -> 49418 | H23: =SUM(H16:H22) -> 40212
A24: Assets and disposal groups classified as held for sale | B24: 1927 | D24: 0 | E24: 3364 | F24: 6865 | G24: 364 | H24: 98
B25: 6834 | C25: 4441 | D25: =SUM(D23:D24) -> 35554 | E25: =SUM(E23:E24) -> 51709 | F25: =SUM(F23:F24) -> 65701 | G25: =SUM(G23:G24) -> 49782 | H25: =SUM(H23:H24) -> 40310
A26: Total assets | B26: 16370 | C26: 17505 | D26: =D14+D23 -> 143517 | E26: =E14+E23 -> 193245 | F26: =F14+F23 -> 195456 | G26: =G14+G23 -> 164653 | H26: =H14+H23 -> 133213
A27: EQUITY AND LIABILITIES
A28: Capital and reserves | D28: 0 | E28: 0 | F28: 0 | G28: 0 | H28: 0
A29: Ordinary share capital and premium | B29: 10434 | C29: 10701 | D29: 81863 | E29: 78279 | F29: 20507 | G29: 9801 | H29: 9898
A30: Reserves | B30: =-1029-148 -> -1177 | C30: -1237 | D30: -5324 | E30: 8249 | F30: 62347 | G30: 46815 | H30: 33350
A31: Accumulated losses | B31: -9778 | C31: -8540 | D31: -23442 | E31: -71495 | F31: 0 | G31: 0 | H31: 0
A32: Preference share capital and premium | D32: 5013 | E32: 5013 | F32: 3381 | G32: 3497 | H32: 3837
A33: Total equity attributable to equity holders of the parent | B33: -521 | C33: 924 | D33: =SUM(D28:D32) -> 58110 | E33: =SUM(E28:E32) -> 20046 | F33: =SUM(F28:F32) -> 86235 | G33: =SUM(G28:G32) -> 60113 | H33: =SUM(H28:H32) -> 47085
A34: Non-controlling interests | B34: 1162 | C34: 1166 | D34: 2830 | E34: 7609 | F34: 1541 | G34: 6655 | H34: 6678
A35: Total equity | B35: 641 | C35: 2090 | D35: =SUM(D33:D34) -> 60940 | E35: =SUM(E33:E34) -> 27655 | F35: =SUM(F33:F34) -> 87776 | G35: =SUM(G33:G34) -> 66768 | H35: =SUM(H33:H34) -> 53763
A36: Non-current liabilities
A37: Interest-bearing loans and borrowings | B37: 2027 | C37: 0 | D37: 30321 | E37: 11405 | F37: 55580 | G37: 45041 | H37: 33858
A38: Employee benefits | B38: 115 | C38: 205 | D38: 531 | E38: 1880 | F38: 868 | G38: 722 | H38: 705
A39: Deferred taxation liabilities | B39: 556 | C39: 752 | D39: 5400 | E39: 10699 | F39: 10878 | G39: 9652 | H39: 7763
A40: Provisions | B40: 182 | C40: 338 | D40: 1113 | E40: 3203 | F40: 1603 | G40: 2609 | H40: 2094
...

Sheet Cash Flow
A1: Statement of cash flows for the year ended 30 June 2014 | B1: 2018 Rm | C1: 2017 Rm | D1: 2016 Rm | E1: 2015 Rm | F1: 2014 Rm | G1: 2013 Rm
A2: CASH FLOWS FROM OPERATING ACTIVITIES
A3: Cash generated from operations | C3: 5975 | D3: 2036 | E3: 26706 | F3: 21317 | G3: 12698
A4: Net movement in unsecured instalment sale and loan receivables | C4: - | D4: -25 | E4: -218 | F4: -385 | G4: -2090
A5: Dividends received
A6: Net dividends paid | C6: -8652 | D6: -142 | E6: -3931 | F6: -1818 | G6: -696
A7: Net finance charges | C7: -5739 | D7: -186 | E7: -1232 | F7: -1842 | G7: -1599
A8: Taxation paid | C8: -3298 | D8: -208 | E8: -1039 | F8: -1592 | G8: -1093
A9: Net cash inflow from operating activities | C9: -11714 | D9: 1475 | E9: 20286 | F9: 15680 | G9: 7220
A10: CASH FLOWS FROM INVESTING ACTIVITIES
A11: Additions to property, plant and equipment and investment property | C11: -10472 | D11: -520 | E11: -4679 | F11: -4948 | G11: -6748
A12: Additions to intangible assets | C12: -799 | D12: -167 | E12: -258 | F12: -381 | G12: -368
A13: Proceeds on disposal of property, plant and equipment, investment property
A14: and intangible assets | C14: 266 | D14: 47 | E14: 213 | F14: 451 | G14: 302
A15: Acquisition of subsidiaries and businesses, net of cash on hand at acquisition | C15: -7144 | D15: -2926 | E15: -13366 | F15: -6473 | G15: -379
A16: Disposal of subsidiaries and businesses, net of cash on hand at disposal | C16: -192 | E16: 0 | F16: 1955 | G16: -13
A17: Increase in investments and loans | C17: -280 | D17: -125 | E17: 22 | F17: -5078 | G17: -122
A18: Increase/(decrease) in treasury shares | C18: 917 | E18: -6 | F18: 284 | G18: 65
A19: Increase in short-term loans receivable | C19: 281 | D19: -273 | E19: -2892 | F19: -2211 | G19: -969
A20: Net decrease in investments in equity accounted companies | C20: -8046 | D20: -221 | E20: -164 | F20: 1 | G20: 47
A21: Transactions with non-controlling interests | C21: - | E21: -103 | F21: 29 | G21: -465
A22: Net cash outflow from investing activities | C22: -25469 | D22: -4185 | E22: -21233 | F22: -16371 | G22: -8650
A23: CASH FLOWS FROM FINANCING ACTIVITIES
A24: Proceeds from ordinary shares issued | D24: 1683 | E24: 18200
A25: Proceeds from preference shares issued | D25: 33 | E25: 2000
A26: Share issue expenses | C26: 15 | D26: -14 | E26: -386 | F26: -2 | G26: -1
A27: Preference shares redeemed | C27: - | D27: - | E27: -499 | F27: -378 | G27: -398
A28: Capital distribution paid | C28: -1435 | E28: 0 | F28: - | G28: -318
A29: Increase in treasury shares | D29: -3
A30: Transactions with non-controlling interests | D30: -76
A31: (Decrease)/increase in bank overdrafts and short-term facilities | C31: 14968 | D31: 489 | E31: -1106 | F31: -443 | G31: 8
A32: Increase in long-term interest-bearing loans and borrowings | C32: -10664 | D32: 1319 | E32: 12052 | F32: 11206 | G32: 7325
A33: Decrease in short-term interest-bearing loans and borrowings | C33: 35202 | D33: -533 | E33: -6522 | F33: -3722 | G33: -5365
A34: Net cash inflow from financing activities | C34: 38086 | D34: 2898 | E34: 23739 | F34: 6661 | G34: 1251
A35: NET INCREASE/(DECREASE) IN CASH AND CASH EQUIVALENTS | C35: 902 | D35: 188 | E35: 22792 | F35: 5970 | G35: -179
A36: Cash and cash equivalents at beginning of the year | C36: 10614 | D36: -121 | E36: 16341 | F36: 9249 | G36: 8057
A37: Effects of exchange rate translations on cash and cash equivalents | C37: -370 | D37: 294 | E37: -1228 | F37: 1122 | G37: 1371
A38: CASH AND CASH EQUIVALENTS AT END OF YEAR | C38: 11146 | D38: 2861 | E38: 37905 | F38: 16341 | G38: 9249

Sheet Ratios
B1: Ratio Analysis
A2: 1. Liquidity Ratios
A3: Year | B3: Current Assets (Rm) | C3: Current Liabilities (Rm) | D3: Current Ratio
A4: 2012 | B4: ='Financial Position'!H25 -> 40310 | C4: ='Financial Position'!H53 -> 34910 | D4: ='Financial Position'!H25/'Financial Position'!H53 -> 1.1546835
A5: 2013 | B5: ='Financial Position'!G25 -> 49782 | C5: ='Financial Position'!G53 -> 39994 | D5: ='Financial Position'!G25/'Financial Position'!G53 -> 1.2447367
A6: 2014 | B6: ='Financial Position'!F25 -> 65701 | C6: ='Financial Position'!F53 -> 45228 | D6: ='Financial Position'!F25/'Financial Position'!F53 -> 1.4526621
A7: 2015 | B7: ='Financial Position'!E25 -> 51709 | C7: ='Financial Position'!E53 -> 115713 | D7: ='Financial Position'!E25/'Financial Position'!E53 -> 0.44687287
A8: 2016 | B8: ='Financial Position'!D25 -> 35554 | C8: ='Financial Position'!D53 -> 38735 | D8: ='Financial Position'!D25/'Financial Position'!D53 -> 0.91787789
A9: 2017 | B9: ='Financial Position'!C25 -> 4441 | C9: ='Financial Position'!C53 -> 14028 | D9: =B9/C9 -> 0.31658112
A10: 2018 | B10: ='Financial Position'!B25 -> 6834 | C10: ='Financial Position'!B53 -> 12780 | D10: =B10/C10 -> 0.53474178
A12: Liquidity improved from 2012 to 2014.
A13: The ratio collapsed to 0.45 in 2015.
A14: A ratio below 1 indicates that short-term liabilities exceeded current assets.
A15: This was a major warning sign of financial distress.
A17: 2. Quick Ratio
A18: Year | C18: Quick Ratio
A19: 2012 | B19: ='Financial Position'!H25-'Financial Position'!H17 -> 25771 | C19: =B19/'Financial Position'!H53 -> 0.73821255
A20: 2013 | B20: ='Financial Position'!G25-'Financial Position'!G17 -> 33335 | C20: =B20/'Financial Position'!G53 -> 0.83350003
A21: 2014 | B21: ='Financial Position'!F25-'Financial Position'!F17 -> 47780 | C21: =B21/'Financial Position'!F53 -> 1.0564252
A22: 2015 | B22: ='Financial Position'!E25-'Financial Position'!E17 -> 24078 | C22: =B22/'Financial Position'!E53 -> 0.20808379
A23: 2016 | B23: ='Financial Position'!D25-'Financial Position'!D17 -> 21763 | C23: =B23/'Financial Position'!D53 -> 0.56184329
A24: 2017 | B24: ='Financial Position'!C25-'Financial Position'!C17 -> 1885 | C24: =B24/'Financial Position'!C53 -> 0.13437411
A25: 2018 | B25: ='Financial Position'!B25-'Financial Position'!B17 -> 4679 | C25: =B25/'Financial Position'!B53 -> 0.36611894
A27: The ratio fell sharply after 2014.
A28: Indicates growing dependence on inventory to meet obligations.
A29: Serious liquidity concerns emerged before the scandal became public.
A31: 3. Solvency Ratios
A32: Year | B32: Debt (Rm) | C32: Equity (Rm) | D32: D/E Ratio
A33: 2012 | B33: ='Financial Position'!H37+'Financial Position'!H47 -> 39050 | C33: ='Financial Position'!H35 -> 53763 | D33: =B33/C33 -> 0.72633596 | F33: ='Financial Position'!H37+'Financial Position'!H47 -> 39050
A34: 2013 | B34: ='Financial Position'!G37+'Financial Position'!G47 -> 50158 | C34: ='Financial Position'!G35 -> 66768 | D34: =B34/C34 -> 0.75122813 | F34: ='Financial Position'!G37+'Financial Position'!G47 -> 50158
A35: 2014 | B35: ='Financial Position'!F37+'Financial Position'!F47 -> 61991 | C35: ='Financial Position'!F35 -> 87776 | D35: =B35/C35 -> 0.70624089 | F35: ='Financial Position'!F37+'Financial Position'!F47 -> 61991
A36: 2015 | B36: ='Financial Position'!E37+'Financial Position'!E47 -> 79295 | C36: ='Financial Position'!E35 -> 27655 | D36: =B36/C36 -> 2.8672934 | F36: ='Financial Position'!E37+'Financial Position'!E47 -> 79295
A37: 2016 | B37: ='Financial Position'!D37+'Financial Position'!D47 -> 50096 | C37: ='Financial Position'!D35 -> 60940 | D37: =B37/C37 -> 0.82205448 | F37: ='Financial Position'!D37+'Financial Position'!D47 -> 50096
A38: 2017 | B38: ='Financial Position'!C37+'Financial Position'!C47 -> 8609 | C38: ='Financial Position'!C35 -> 2090 | D38: =B38/C38 -> 4.1191388
A39: 2018 | B39: ='Financial Position'!B37+'Financial Position'!B47 -> 10345 | C39: ='Financial Position'!B35 -> 641 | D39: =B39/C39 -> 16.138846
A43: Debt Ratio
A44: Year | B44: Debt Ratio
A45: 2012 | B45: =B33/'Financial Position'!H26 -> 0.29313956
A46: 2013 | B46: =B34/'Financial Position'!G26 -> 0.30462852
A47: 2014 | B47: =B35/'Financial Position'!F26 -> 0.3171609
...

Sheet RedFlags_Timeline
A1: STEINHOFF — CHRONOLOGY OF KEY EVENTS & RED FLAGS (2013–2019+)
A2: Date/Period | B2: Event | C2: Category | D2: Red-flag / financial-analytics indicator
A3: 2013–2016 | B3: Aggressive debt- and equity-funded acquisition spree (Pepkor, Mattress Firm, Poundland, Conforama, KIKA/Leiner) | C3: Governance / Strategy | D3: Goodwill rises from R15.6bn (2012) to R48.5bn (2015) — 3x in 3 years; M&A-fuelled growth is a classic pre-fraud pattern used to mask organic underperformance
A4: FY2015 (restated) | B4: Comparatives later show current liabilities of R115.7bn vs current assets of R51.7bn; accumulated losses of R71.5bn appear in restated accounts | C4: Liquidity / Solvency | D4: Current ratio collapses to 0.45x and Debt/Equity spikes to 2.87x — a going-concern-level liquidity red flag, consistent with short-term debt reclassification once covenant breaches were disclosed
A5: 2015–2016 | B5: Related-party transactions with entities linked to a 'senior management executive' (Markus Jooste) and offshore structures (Campion Capital, Southern View Finance, etc.) used to book fictitious profit on disposals | C5: Fraud mechanism | D5: Off-balance-sheet special purpose entities recording circular/fictitious income — classic related-party earnings-management red flag
A6: H1 FY2017 (to Mar 2017) | B6: Interim results show cash flow from operations of only EUR13m for the six months to March 2017 (vs a much stronger prior-year comparable half); free cash flow -EUR403m vs +EUR164m in H1 FY2016 | C6: Cash flow / Earnings quality | D6: A profit figure (EUR706m net income for the period) that is not backed by operating cash generation is a classic earnings-quality red flag — cash flow deteriorated sharply months before the December 2017 disclosure
A7: Aug 2017 | B7: Auditor (Deloitte) delays sign-off on FY2017 results | C7: Audit | D7: Audit delay of published results is a top-tier red flag for financial statement fraud
A8: 5 Dec 2017 | B8: CEO Markus Jooste resigns with immediate effect; board discloses 'accounting irregularities' | C8: Governance trigger | D8: Sudden, unexplained C-suite resignation coinciding with results delay
A9: 6–8 Dec 2017 | B9: Share price falls ~85–98% in one week; ~€10.3bn (~R150bn+) wiped off market value in days; Moody's cuts credit rating to junk | C9: Market reaction | D9: Extreme, rapid market repricing confirms the market had not priced in the fraud — evidence of prior information asymmetry
A10: 2018 | B10: PwC forensic investigation commissioned by the board | C10: Investigation | D10: External forensic investigation triggered by predication (auditor concerns, whistle-blower/related-party evidence, executive resignation)
A11: Mar 2019 | B11: PwC summary findings released: ~€6.5bn (~$7.4bn) of fictitious/irregular transactions identified from 2009–2017, inflating profits and asset values | C11: Investigation outcome | D11: Confirms multi-year, systemic overstatement of income and non-current assets (goodwill/intangibles) rather than an isolated misstatement
A12: 2019 | B12: Restated FY2017 (and FY2016 comparative) financial statements finally published, showing large prior-year losses and asset write-downs | C12: Financial reporting | D12: Company total assets fall from R195bn (2014) to R143.5bn (2016) even before full restatement — early evidence of overstated non-current assets
A13: 2019–2023 | B13: €21bn Steinhoff creditor restructuring / lock-up agreements; multiple class actions and regulatory settlements (incl. ~R25bn global settlement) | C13: Legal/Regulatory | D13: Debt-for-equity restructuring confirms the balance sheet could not support previously reported debt levels once fictitious assets were removed

Sheet Distress_Models
A1: FINANCIAL DISTRESS & EARNINGS-MANIPULATION ANALYTICS — STEINHOFF INTERNATIONAL
A3: A. Altman Z''-Score (Emerging-Market / Book-Value Model, Altman 1995)
A4: Year | B4: 2013 | C4: 2014 | D4: 2015 | E4: 2016 | F4: 2017 | G4: 2018
A5: Working Capital (CA - CL), Rm | B5: ='Financial Position'!G25-'Financial Position'!G53 -> 9788 | C5: ='Financial Position'!F25-'Financial Position'!F53 -> 20473 | D5: ='Financial Position'!E25-'Financial Position'!E53 -> -64004 | E5: ='Financial Position'!D25-'Financial Position'!D53 -> -3181 | F5: ='Financial Position'!C25-'Financial Position'!C53 -> -9587 | G5: ='Financial Position'!B25-'Financial Position'!B53 -> -5946
A6: Total Assets, Rm | B6: ='Financial Position'!G26 -> 164653 | C6: ='Financial Position'!F26 -> 195456 | D6: ='Financial Position'!E26 -> 193245 | E6: ='Financial Position'!D26 -> 143517 | F6: ='Financial Position'!C26 -> 17505 | G6: ='Financial Position'!B26 -> 16370
A7: X1 = Working Capital / Total Assets | B7: =B5/B6 -> 0.059446229 | C7: =C5/C6 -> 0.1047448 | D7: =D5/D6 -> -0.3312065 | E7: =E5/E6 -> -0.022164622 | F7: =F5/F6 -> -0.54767209 | G7: =G5/G6 -> -0.36322541
A8: Retained Earnings (Accum. losses), Rm | B8: ='Financial Position'!G31 -> 0 | C8: ='Financial Position'!F31 -> 0 | D8: ='Financial Position'!E31 -> -71495 | E8: ='Financial Position'!D31 -> -23442 | F8: ='Financial Position'!C31 -> -8540 | G8: ='Financial Position'!B31 -> -9778
A9: X2 = Retained Earnings / Total Assets | B9: =B8/B6 -> 0 | C9: =C8/C6 -> 0 | D9: =D8/D6 -> -0.36997076 | E9: =E8/E6 -> -0.16333953 | F9: =F8/F6 -> -0.48786061 | G9: =G8/G6 -> -0.59731216
A10: EBIT (Operating profit), Rm | B10: ='Income Statement'!G10 -> 9459 | C10: ='Income Statement'!F10 -> 14122 | D10: ='Income Statement'!E10 -> 5381 | E10: ='Income Statement'!D10 -> 9298 | F10: ='Income Statement'!C10 -> -2256 | G10: ='Income Statement'!B10 -> 1253
A11: X3 = EBIT / Total Assets | B11: =B10/B6 -> 0.057448088 | C11: =C10/C6 -> 0.072251555 | D11: =D10/D6 -> 0.027845481 | E11: =E10/E6 -> 0.06478675 | F11: =F10/F6 -> -0.12887746 | G11: =G10/G6 -> 0.076542456
A12: Book Value of Equity, Rm | B12: ='Financial Position'!G35 -> 66768 | C12: ='Financial Position'!F35 -> 87776 | D12: ='Financial Position'!E35 -> 27655 | E12: ='Financial Position'!D35 -> 60940 | F12: ='Financial Position'!C35 -> 2090 | G12: ='Financial Position'!B35 -> 641
A13: Total Liabilities, Rm | B13: ='Financial Position'!G54-'Financial Position'!G35 -> 98249 | C13: ='Financial Position'!F54-'Financial Position'!F35 -> 114545 | D13: ='Financial Position'!E54-'Financial Position'!E35 -> 143869 | E13: ='Financial Position'!D54-'Financial Position'!D35 -> 76720 | F13: ='Financial Position'!C54-'Financial Position'!C35 -> 15415 | G13: ='Financial Position'!B54-'Financial Position'!B35 -> 15729
A14: X4 = Book Equity / Total Liabilities | B14: =B12/B13 -> 0.67957944 | C14: =C12/C13 -> 0.76630145 | D14: =D12/D13 -> 0.19222348 | E14: =E12/E13 -> 0.794317 | F14: =F12/F13 -> 0.13558223 | G14: =G12/G13 -> 0.04075275
A16: Z''-Score = 6.56X1 + 3.26X2 + 6.72X3 + 1.05X4 | B16: =6.56*B7+3.26*B9+6.72*B11+1.05*B14 -> 1.4895768 | C16: =6.56*C7+3.26*C9+6.72*C11+1.05*C14 -> 1.9772729 | D16: =6.56*D7+3.26*D9+6.72*D11+1.05*D14 -> -2.989863 | E16: =6.56*E7+3.26*E9+6.72*E11+1.05*E14 -> 0.59151301 | F16: =6.56*F7+3.26*F9+6.72*F11+1.05*F14 -> -5.9068497 | G16: =6.56*G7+3.26*G9+6.72*G11+1.05*G14 -> -3.7728406
A17: Zone (Z'' > 2.6 Safe | 1.1-2.6 Grey | < 1.1 Distress) | B17: =IF(B16>2.6,"Safe",IF(B16>1.1,"Grey","Distress")) -> Grey | C17: =IF(C16>2.6,"Safe",IF(C16>1.1,"Grey","Distress")) -> Grey | D17: =IF(D16>2.6,"Safe",IF(D16>1.1,"Grey","Distress")) -> Distress | E17: =IF(E16>2.6,"Safe",IF(E16>1.1,"Grey","Distress")) -> Distress | F17: =IF(F16>2.6,"Safe",IF(F16>1.1,"Grey","Distress")) -> Distress | G17: =IF(G16>2.6,"Safe",IF(G16>1.1,"Grey","Distress")) -> Distress
A19: a Z''-Score trend crossing from Safe/Grey into the Distress zone ahead of the December 2017 , The Company financials already signalled deteriorating solvency, independent of the market's slower repricing.
A22: B. Earnings-Manipulation Red-Flag Indices (Beneish-style, partial — see note)
A23: Year | B23: 2013 | C23: 2014 | D23: 2015 | E23: 2016 | F23: 2017 | G23: 2018
A24: Trade & other receivables (current), Rm | B24: ='Financial Position'!G18 -> 20039 | C24: ='Financial Position'!F18 -> 18112 | D24: ='Financial Position'!E18 -> 10160 | E24: ='Financial Position'!D18 -> 6039 | F24: ='Financial Position'!C18 -> 1055 | G24: ='Financial Position'!B18 -> 1216
A25: Sales / Revenue, Rm | B25: ='Income Statement'!G2 -> 97938 | C25: ='Income Statement'!F2 -> 117364 | D25: ='Income Statement'!E2 -> 43445 | E25: ='Income Statement'!D2 -> 99848 | F25: ='Income Statement'!C2 -> 187095 | G25: ='Income Statement'!B2 -> 200477
A26: Gross Margin % (Gross profit / Sales) | B26: ='Income Statement'!G4/'Income Statement'!G2 -> 0.35120178 | C26: ='Income Statement'!F4/'Income Statement'!F2 -> 0.35716233 | D26: ='Income Statement'!E4/'Income Statement'!E2 -> 0.31396018 | E26: ='Income Statement'!D4/'Income Statement'!D2 -> 0.31022154 | F26: ='Income Statement'!C4/'Income Statement'!C2 -> 0.3882573 | G26: ='Income Statement'!B4/'Income Statement'!B2 -> 0.38674761
A27: Leverage (Total Liabilities / Total Assets) | B27: =('Financial Position'!G54-'Financial Position'!G35)/'Financial Position'!G26 -> 0.59670337 | C27: =('Financial Position'!F54-'Financial Position'!F35)/'Financial Position'!F26 -> 0.58603982 | D27: =('Financial Position'!E54-'Financial Position'!E35)/'Financial Position'!E26 -> 0.74449015 | E27: =('Financial Position'!D54-'Financial Position'!D35)/'Financial Position'!D26 -> 0.53457082 | F27: =('Financial Position'!C54-'Financial Position'!C35)/'Financial Position'!C26 -> 0.88060554 | G27: =('Financial Position'!B54-'Financial Position'!B35)/'Financial Position'!B26 -> 0.96084301
A28: Non-Current-Asset Intensity (1 - (CA+PPE)/TA) | B28: =1-(('Financial Position'!G25+'Financial Position'!G7)/'Financial Position'!G26) -> 0.42497859 | C28: =1-(('Financial Position'!F25+'Financial Position'!F7)/'Financial Position'!F26) -> 0.38760642 | D28: =1-(('Financial Position'!E25+'Financial Position'!E7)/'Financial Position'!E26) -> 0.50516184 | E28: =1-(('Financial Position'!D25+'Financial Position'!D7)/'Financial Position'!D26) -> 0.6897162 | F28: =1-(('Financial Position'!C25+'Financial Position'!C7)/'Financial Position'!C26) -> 0.55766924 | G28: =1-(('Financial Position'!B25+'Financial Position'!B7)/'Financial Position'!B26) -> 0.45143555
A30: DSRI (Days-Sales-Receivables Index) | C30: =(C24/C25)/(B24/B25) -> 0.75423502 | D30: =(D24/D25)/(C24/C25) -> 1.515383 | E30: =(E24/E25)/(D24/D25) -> 0.25862574 | F30: =(F24/F25)/(E24/E25) -> 0.093231918 | G30: =(G24/G25)/(F24/F25) -> 1.0756692
A31: GMI (Gross Margin Index, prior/current) | C31: =B26/C26 -> 0.98331136 | D31: =C26/D26 -> 1.1376039 | E31: =D26/E26 -> 1.0120515 | F31: =E26/F26 -> 0.79901018 | G31: =F26/G26 -> 1.0039036
A32: SGI (Sales Growth Index) | C32: =C25/B25 -> 1.19835 | D32: =D25/C25 -> 0.37017314 | E32: =E25/D25 -> 2.2982622 | F32: =F25/E25 -> 1.8737982 | G32: =G25/F25 -> 1.0715252
A33: LVGI (Leverage Index) | C33: =C27/B27 -> 0.98212924 | D33: =D27/C27 -> 1.2703747 | E33: =E27/D27 -> 0.71803611 | F33: =F27/E27 -> 1.6473132 | G33: =G27/F27 -> 1.0911162
A34: AQI (Asset Quality Index) | C34: =C28/B28 -> 0.91206104 | D34: =D28/C28 -> 1.3032855 | E34: =E28/D28 -> 1.3653371 | F34: =F28/E28 -> 0.80854884 | G34: =G28/F28 -> 0.80950413
A36: Note: the full 8-variable Beneish M-Score also requires DEPI (depreciation index), SGAI (SG&A index) and TATA (total accruals/total assets, which needs operating cash flow). This summarised workbook only contains operating cash flow for FY2013-FY2014 (Cash Flow tab) and does not disaggregate SG&A or depreciation, so a defensible full M-Score cannot be computed from these statements alone — this is itself worth noting in Q1.3/Q4.1 as a disclosure-granularity red flag. The five indices above (DSRI, GMI, SGI, LVGI, AQI) are the subset computable from the available summarised financials; values > 1 (shaded red) indicate a manipulation-consistent direction for that individual index. For a full M-Score, source the FY2013-2017 detailed annual reports from steinhoffinternational.com investor relations.

Sheet KPI's
A1: KPI SCORECARD — STEINHOFF INTERNATIONAL (live-linked to Ratios tab)
A2: Traffic-light format: Green = Healthy | Amber = Warning | Red = Critical. Thresholds are shown in column A next to each KPI.
A3: KPI | B3: 2013 | C3: 2014 | D3: 2015 | E3: 2016 | F3: 2017 | G3: 2018
A4: Revenue Growth % (same-currency blocks only) | B4: no FY2012 base* | C4: ='Income Statement'!F2/'Income Statement'!G2-1 -> 0.19834998 | D4: ='Income Statement'!E2/'Income Statement'!F2-1 -> -0.62982686 | E4: ='Income Statement'!D2/'Income Statement'!E2-1 -> 1.2982622 | F4: 0.874 | G4: ='Income Statement'!B2/'Income Statement'!C2-1 -> 0.071525161
A5: Gross Margin % | B5: =Ratios!D59 -> 0.35120178 | C5: =Ratios!D60 -> 0.35716233 | D5: =Ratios!D61 -> 0.31396018 | E5: =Ratios!D62 -> 0.31022154 | F5: =Ratios!D63 -> 0.3882573 | G5: =Ratios!D64 -> 0.38674761
A6: Return on Assets (ROA) | B6: =Ratios!B92 -> 0.048277286 | C6: =Ratios!B93 -> 0.050461485 | D6: =Ratios!B94 -> 0.059261559 | E6: =Ratios!B95 -> 0.10723468 | F6: =Ratios!B96 -> -3.4312482 | G6: =Ratios!B97 -> -1.1403177
A7: Return on Equity (ROE) | B7: =Ratios!B102 -> 0.11905404 | C7: =Ratios!B103 -> 0.11236557 | D7: =Ratios!B104 -> 0.41410233 | E7: =Ratios!B105 -> 0.25254349 | F7: =Ratios!B106 -> -28.738756 | G7: =Ratios!B107 -> -29.121685
A8: Current Ratio | B8: =Ratios!D5 -> 1.2447367 | C8: =Ratios!D6 -> 1.4526621 | D8: =Ratios!D7 -> 0.44687287 | E8: =Ratios!D8 -> 0.91787789 | F8: =Ratios!D9 -> 0.31658112 | G8: =Ratios!D10 -> 0.53474178
A9: Debt Ratio | B9: =Ratios!B46 -> 0.30462852 | C9: =Ratios!B47 -> 0.3171609 | D9: =Ratios!B48 -> 0.41033403 | E9: =Ratios!B49 -> 0.34905969 | F9: =Ratios!B50 -> 0.49180234 | G9: =Ratios!B51 -> 0.63194869

Sheet SharePrice_Data
A1: STEINHOFF SHARE PRICE — VERIFIED ANCHOR POINTS (JSE:SNH, ZAR)
A2: Date | B2: Event | C2: Price (ZAR) | D2: Market Cap (Rbn) | E2: Source | F2: Category
A3: 2016-04-01 | B3: Pre-decline local peak, ahead of slow decline into 2017 | C3: 95 | E3: CNBC Africa, "Inside the Steinhoff saga" (Jun 2018) | F3: Before
A4: 2017-05-23 | B4: Last stable trading level before the December crash | C4: 50.25 | D4: 240.5 | E4: CNBC Africa, "Inside the Steinhoff saga" (Jun 2018) | F4: Before
A5: 2017-12-01 | B5: Approx. price immediately before resignation announcement | C5: 56 | E5: CNBC Africa, "Inside the Steinhoff saga" (Jun 2018) | F5: Before
A6: 2017-12-06 | B6: Jooste resignation + "accounting irregularities" disclosed after market close | C6: 56 | E6: Public record / Steinhoff SENS announcement | F6: During
A7: 2017-12-08 | B7: End of first crash week — approx. 85-98% one-week decline; ~R150bn+ (~EUR10.3bn) of market value erased | C7: ~1.00-8.00 (range unverified daily low) | E7: Bloomberg/Reuters/BizNews, Dec 2017 (cross-check exact daily close against JSE data before using in the model) | F7: During
A8: 2023-10-13 | B8: JSE delisting — final trading day | C8: 0.02 | D8: 0.0854 (total mkt cap at delisting) | E8: JSE delisting notice / afx.kwayisi.org | F8: After

Sheet Forecast_5Y
A1: INTEGRATED 5-YEAR FORECAST — 'NO-SCANDAL' COUNTERFACTUAL vs ACTUAL OUTCOMES (Rm)
A3: Key assumptions (documented)
A4: Revenue growth p.a. | B4: 0.05 | D4: Conservative mid-single-digit organic growth. NOT extrapolated from the FY2013-FY2016 CAGR because that period includes major, non-organic scope changes (acquisitions/deconsolidations) that distort a simple CAGR; 5% approximates management's pre-scandal growth guidance and broad retail-sector norms.
A5: Operating (EBIT) margin | B5: 0.105 | D5: Average of FY2013-FY2016 actual Operating Profit Margin (9.7%, 12.0%, 12.4%, 9.3%) per the corrected Ratios tab, rounded to 10.5%.
A6: Effective tax rate | B6: 0.2 | D6: Blend of the FY2013-FY2016 historical effective rate (~12-18%) and the SA statutory corporate rate (28% at the time), reflecting normalised ongoing profitability rather than the very low effective rates seen in some historical years.
A7: Asset turnover (Revenue / Total Assets) | B7: 0.6 | D7: Average of FY2013, FY2014 and FY2016 actual Asset Turnover per the corrected Ratios tab (FY2015 excluded as a distorted outlier). Used both to project Total Assets and, via Damodaran's sales-to-capital approach, to estimate reinvestment (capex + working capital) needed to fund growth.
A8: Dividend payout ratio | B8: 0 | D8: Assumed 0% (fully retained earnings) for simplicity in the counterfactual — conservative, since any actual payout would only reduce the counterfactual equity build-up shown here.
A9: Reinvestment rate (% of NOPAT) — normalised organic capex/NWC, no further M&A | B9: 0.3 | D9: Materially lower than Steinhoff's actual historical capital intensity (Total Assets/Revenue implied a reinvestment need of ~R1.67 for every R1 of new revenue), because that historical intensity was driven by debt-funded M&A goodwill, not organic reinvestment. The counterfactual assumes no further acquisitions, so a standard organic reinvestment rate is used instead.
A11: Rm | B11: FY2016 (base, Actual) | C11: FY2017E (counterfactual) | D11: FY2018E (counterfactual) | E11: FY2019E (counterfactual) | F11: FY2020E (counterfactual) | G11: FY2021E (counterfactual) | H11: FY2017 (Actual) | I11: FY2018 (Actual)
A12: Revenue | B12: ='Income Statement'!D2 -> 99848 | C12: =B12*(1+$B$4) -> 104840.4 | D12: =C12*(1+$B$4) -> 110082.42 | E12: =D12*(1+$B$4) -> 115586.54 | F12: =E12*(1+$B$4) -> 121365.87 | G12: =F12*(1+$B$4) -> 127434.16 | H12: ='Income Statement'!C2 -> 187095 | I12: ='Income Statement'!B2 -> 200477
A13: EBIT (Operating Profit) | B13: ='Income Statement'!D10 -> 9298 | C13: =C12*$B$5 -> 11008.242 | D13: =D12*$B$5 -> 11558.654 | E13: =E12*$B$5 -> 12136.587 | F13: =F12*$B$5 -> 12743.416 | G13: =G12*$B$5 -> 13380.587 | H13: ='Income Statement'!C10 -> -2256 | I13: ='Income Statement'!B10 -> 1253
A14: Tax on EBIT | B14: =-B13*$B$6 -> -1859.6 | C14: =-C13*$B$6 -> -2201.6484 | D14: =-D13*$B$6 -> -2311.7308 | E14: =-E13*$B$6 -> -2427.3174 | F14: =-F13*$B$6 -> -2548.6832 | G14: =-G13*$B$6 -> -2676.1174
A15: NOPAT | B15: =B13+B14 -> 7438.4 | C15: =C13+C14 -> 8806.5936 | D15: =D13+D14 -> 9246.9233 | E15: =E13+E14 -> 9709.2694 | F15: =F13+F14 -> 10194.733 | G15: =G13+G14 -> 10704.47 | H15: ='Income Statement'!C19 -> -60064 | I15: ='Income Statement'!B19 -> -18667
A16: Reinvestment (capex + ΔNWC, sales-to-capital method) | C16: =C15*$B$9 -> 2641.9781 | D16: =D15*$B$9 -> 2774.077 | E16: =E15*$B$9 -> 2912.7808 | F16: =F15*$B$9 -> 3058.4199 | G16: =G15*$B$9 -> 3211.3409
A17: Unlevered Free Cash Flow (FCFF) | C17: =C15-C16 -> 6164.6155 | D17: =D15-D16 -> 6472.8463 | E17: =E15-E16 -> 6796.4886 | F17: =F15-F16 -> 7136.313 | G17: =G15-G16 -> 7493.1287
A19: Total Assets (implied) | B19: ='Financial Position'!D26 -> 143517 | C19: =C12/$B$7 -> 174734 | D19: =D12/$B$7 -> 183470.7 | E19: =E12/$B$7 -> 192644.24 | F19: =F12/$B$7 -> 202276.45 | G19: =G12/$B$7 -> 212390.27 | H19: ='Financial Position'!C26 -> 17505 | I19: ='Financial Position'!B26 -> 16370
A20: Total Equity (roll-forward, retained earnings) | B20: ='Financial Position'!D35 -> 60940 | C20: =B20+C15*(1-$B$8) -> 69746.594 | D20: =C20+D15*(1-$B$8) -> 78993.517 | E20: =D20+E15*(1-$B$8) -> 88702.786 | F20: =E20+F15*(1-$B$8) -> 98897.519 | G20: =F20+G15*(1-$B$8) -> 109601.99 | H20: ='Financial Position'!C35 -> 2090 | I20: ='Financial Position'!B35 -> 641
A21: Implied Total Liabilities (plug = Assets − Equity) | B21: =B19-B20 -> 82577 | C21: =C19-C20 -> 104987.41 | D21: =D19-D20 -> 104477.18 | E21: =E19-E20 -> 103941.45 | F21: =F19-F20 -> 103378.93 | G21: =G19-G20 -> 102788.28 | H21: =H19-H20 -> 15415 | I21: =I19-I20 -> 15729
A23: Value destruction vs counterfactual
A24: Total Assets: Counterfactual FY2017E/18E vs Actual FY2017/18 | C24: =C19-H19 -> 157229 | D24: =D19-I19 -> 167100.7
A25: Total Equity: Counterfactual FY2017E/18E vs Actual FY2017/18 | C25: =C20-H20 -> 67656.594 | D25: =D20-I20 -> 78352.517

Sheet Valuation
A1: VALUATION — DCF, DDM, RELATIVE MULTIPLES, COST OF EQUITY/WACC, SENSITIVITY
A3: A. Cost of Equity (CAPM) and WACC
A4: Risk-free rate (Rf) — SA 10-yr government bond, ~FY2016 | B4: 0.09
A5: Equity risk premium (South Africa) | B5: 0.065
A6: Levered Beta (JSE retail/consumer conglomerate, illustrative) | B6: 1.1
A7: Cost of debt (pre-tax) — avg finance cost / avg interest-bearing debt | B7: 0.09
A8: Tax rate (link to Forecast assumption) | B8: =Forecast_5Y!B6 -> 0.2
A9: Target Debt / (Debt+Equity) | B9: 0.45
A10: Cost of Equity (Ke) = Rf + Beta × ERP | B10: =B4+B6*B5 -> 0.1615
A11: After-tax Cost of Debt = Kd × (1 − tax) | B11: =B7*(1-B8) -> 0.072
A12: WACC = Ke×(1−D/V) + Kd(1−t)×(D/V) | B12: =B10*(1-B9)+B11*B9 -> 0.121225
A15: B. Discounted Cash Flow (DCF) — FCFF from Forecast_5Y
A17: Terminal growth rate (g) | B17: 0.03
B19: FY2017E | C19: FY2018E | D19: FY2019E | E19: FY2020E | F19: FY2021E
A20: FCFF (Rm) | B20: =Forecast_5Y!C17 -> 6164.6155 | C20: =Forecast_5Y!D17 -> 6472.8463 | D20: =Forecast_5Y!E17 -> 6796.4886 | E20: =Forecast_5Y!F17 -> 7136.313 | F20: =Forecast_5Y!G17 -> 7493.1287
A21: Discount factor = 1/(1+WACC)^n | B21: =1/(1+$B$12)^1 -> 0.89188165 | C21: =1/(1+$B$12)^2 -> 0.79545287 | D21: =1/(1+$B$12)^3 -> 0.70944982 | E21: =1/(1+$B$12)^4 -> 0.63274527 | F21: =1/(1+$B$12)^5 -> 0.5643339
A22: PV of FCFF | B22: =B20*B21 -> 5498.1074 | C22: =C20*C21 -> 5148.8442 | D22: =D20*D21 -> 4821.7676 | E22: =E20*E21 -> 4515.4683 | F22: =F20*F21 -> 4228.6265
A24: Terminal Value (at end FY2021E) = FCFF2021×(1+g)/(WACC−g) | B24: =F20*(1+B17)/(B12-B17) -> 84603.152
A25: PV of Terminal Value | B25: =B24*F21 -> 47744.426
A26: Sum of PV of FCFF (FY2017E-FY2021E) | B26: =SUM(B22:F22) -> 24212.814
A27: Enterprise Value (EV) = ΣPV(FCFF) + PV(TV) | B27: =B26+B25 -> 71957.241
A28: Less: Net Debt (FY2016 actual: interest-bearing debt − cash) | B28: =('Financial Position'!D37+'Financial Position'!D47)-'Financial Position'!D22 -> 43515
A29: Implied Equity Value (counterfactual, no-scandal) | B29: =B27-B28 -> 28442.241
A30: Shares in issue (approx., Rm shares — source: Steinhoff FY2016 annual report) | B30: 4405
A31: Implied Intrinsic Value per Share (ZAR) | B31: =(B29/B30) -> 6.4568083
A33: Actual share price at JSE delisting (13 Oct 2023) | B33: =SharePrice_Data!C8 -> 0.02
A34: Implied value destruction per share (counterfactual − actual) | B34: =B31-B33 -> 6.4368083
A35: Implied % of intrinsic value destroyed | B35: =B34/B31 -> 0.99690249
A38: C. Dividend Discount Model (DDM) — illustrative cross-check
A39: Illustrative only: Steinhoff suspended dividends after Dec-2017. Modelled here on the counterfactual NOPAT with an assumed payout ratio, purely to cross-check the DCF.
A40: Assumed payout ratio | B40: 0.3
A41: FY2021E Dividend = NOPAT × payout | B41: =Forecast_5Y!G15*B40 -> 3211.3409
A42: Next-year dividend D1 = D0 × (1+g) | B42: =B41*(1+B17) -> 3307.6811
A43: DDM Value of Equity = D1 / (Ke − g) | B43: =B42/(B10-B17) -> 25153.468
A44: DDM Implied Value per Share | B44: =B43/B30 -> 5.7102085
A47: D. Relative Valuation — EV/EBITDA multiple cross-check
A48: Peer average EV/EBITDA (global retail conglomerates, illustrative) | B48: 8
A49: FY2021E EBITDA proxy (EBIT, no D&A disaggregation available) | B49: =Forecast_5Y!G13 -> 13380.587
A50: Implied EV (relative) | B50: =B48*B49 -> 107044.7
A51: Less: Net Debt (FY2016 actual) | B51: =('Financial Position'!D37+'Financial Position'!D47)-'Financial Position'!D22 -> 43515
...

Sheet Dashboard
A1: STEINHOFF INTERNATIONAL — EXECUTIVE DASHBOARD
A2: All figures live-linked to the corrected Income Statement / Financial Position / Ratios / Distress_Models tabs.
A4: Year | B4: 2013 | C4: 2014 | D4: 2015 | E4: 2016 | F4: 2017 | G4: 2018
A5: Revenue (Rm) | B5: ='Income Statement'!G2 -> 97938 | C5: ='Income Statement'!F2 -> 117364 | D5: ='Income Statement'!E2 -> 43445 | E5: ='Income Statement'!D2 -> 99848 | F5: ='Income Statement'!C2 -> 187095 | G5: ='Income Statement'!B2 -> 200477
A6: Current Ratio | B6: =Ratios!D5 -> 1.2447367 | C6: =Ratios!D6 -> 1.4526621 | D6: =Ratios!D7 -> 0.44687287 | E6: =Ratios!D8 -> 0.91787789 | F6: =Ratios!D9 -> 0.31658112 | G6: =Ratios!D10 -> 0.53474178
A7: ROA (corrected) | B7: =Ratios!B92 -> 0.048277286 | C7: =Ratios!B93 -> 0.050461485 | D7: =Ratios!B94 -> 0.059261559 | E7: =Ratios!B95 -> 0.10723468 | F7: =Ratios!B96 -> -3.4312482 | G7: =Ratios!B97 -> -1.1403177
A8: ROE | B8: =Ratios!B102 -> 0.11905404 | C8: =Ratios!B103 -> 0.11236557 | D8: =Ratios!B104 -> 0.41410233 | E8: =Ratios!B105 -> 0.25254349 | F8: =Ratios!B106 -> -28.738756 | G8: =Ratios!B107 -> -29.121685
A9: Debt Ratio | B9: =Ratios!B45 -> 0.29313956 | C9: =Ratios!B46 -> 0.30462852 | D9: =Ratios!B47 -> 0.3171609 | E9: =Ratios!B48 -> 0.41033403 | F9: =Ratios!B49 -> 0.34905969 | G9: =Ratios!B50 -> 0.49180234
A10: Altman Z''-Score | B10: =Distress_Models!B16 -> 1.4895768 | C10: =Distress_Models!C16 -> 1.9772729 | D10: =Distress_Models!D16 -> -2.989863 | E10: =Distress_Models!E16 -> 0.59151301 | F10: =Distress_Models!F16 -> -5.9068497 | G10: =Distress_Models!G16 -> -3.7728406
A11: Goodwill % of Total Assets | B11: =Ratios!D124 -> 0.11448319 | C11: =Ratios!D125 -> 0.14228266 | D11: =Ratios!D126 -> 0.25122513 | E11: =Ratios!D127 -> 0.33419734 | F11: =Ratios!D128 -> 0.26238218 | G11: =Ratios!D129 -> 0.27397679
A14: KPI Scorecard — FY2018 vs FY2017 (traffic light)
A15: KPI | B15: FY2017 | C15: FY2018 | D15: Direction
A16: Current Ratio | B16: =Ratios!D9 -> 0.31658112 | C16: =Ratios!D10 -> 0.53474178 | D16: =C16-B16 -> 0.21816066
A17: ROA | B17: =Ratios!B96 -> -3.4312482 | C17: =Ratios!B97 -> -1.1403177 | D17: =C17-B17 -> 2.2909306
A18: ROE | B18: =Ratios!B106 -> -28.738756 | C18: =Ratios!B107 -> -29.121685 | D18: =C18-B18 -> -0.38292889
A19: Debt Ratio | B19: =Ratios!B50 -> 0.49180234 | C19: =Ratios!B51 -> 0.63194869 | D19: =C19-B19 -> 0.14014634
A20: Altman Z''-Score | B20: =Distress_Models!F16 -> -5.9068497 | C20: =Distress_Models!G16 -> -3.7728406 | D20: =C20-B20 -> 2.1340091
A21: Net Profit Margin | B21: =Ratios!B84 -> -0.32103477 | C21: =Ratios!B85 -> -0.093112926 | D21: =C21-B21 -> 0.22792184
